----------------------------------------------------------------------
Ran 4 tests in 0.119s

OK
Traceback (most recent call last):
  File "/usr/lib/python2.7/unittest/case.py", line 329, in run
    testMethod()
  File "/home/lsandov1/repos/patchtest-oe/tests/base.py", line 43, in wrapper
    return f(*args, **kwds)
  File "/home/lsandov1/repos/patchtest-oe/tests/test_metadata_src_uri.py", line 53, in test_src_uri_checksums_not_changed
    payload = str(patch)
UnicodeEncodeError: 'ascii' codec can't encode characters in position 222-223: ordinal not in range(128)
None
Traceback (most recent call last):
  File "/usr/lib/python2.7/unittest/case.py", line 329, in run
    testMethod()
  File "/home/lsandov1/repos/patchtest-oe/tests/base.py", line 43, in wrapper
    return f(*args, **kwds)
  File "/home/lsandov1/repos/patchtest-oe/tests/test_metadata_src_uri.py", line 24, in test_src_uri_left_files
    payload = str(patch)
UnicodeEncodeError: 'ascii' codec can't encode characters in position 222-223: ordinal not in range(128)
None
Traceback (most recent call last):
  File "/usr/lib/python2.7/unittest/case.py", line 329, in run
    testMethod()
  File "/home/lsandov1/repos/patchtest-oe/tests/base.py", line 43, in wrapper
    return f(*args, **kwds)
  File "/home/lsandov1/repos/patchtest-oe/tests/test_metadata_lic_files_chksum.py", line 44, in test_lic_files_chksum_presence
    payload = str(patch)
UnicodeEncodeError: 'ascii' codec can't encode characters in position 219-220: ordinal not in range(128)
None
----------------------------------------------------------------------
Ran 25 tests in 0.114s

OK
